<?xml version="1.0" encoding="utf-8"?>
<!--
Copyright Amazon.com, Inc. or its affiliates. All Rights Reserved.

Licensed under the Apache License, Version 2.0 (the "License").
You may not use this file except in compliance with the License.
You may obtain a copy of the License at

    http://www.apache.org/licenses/LICENSE-2.0

Unless required by applicable law or agreed to in writing, software
distributed under the License is distributed on an "AS IS" BASIS,
WITHOUT WARRANTIES OR CONDITIONS OF ANY KIND, either express or implied.
See the License for the specific language governing permissions and
limitations under the License.
-->
<robot
  name="deepracer_single_cam" xmlns:xacro="http://www.ros.org/wiki/xacro">
  <link 
    name="base_link" />
  <link
    name="chassis">
    <inertial>
      <origin
        xyz="0 0 0"
        rpy="0 0 0" />
      <mass value="1.9068" />
	    <inertia ixx="0.004151895" ixy="0"             ixz="0"
	                               iyy="0.010379737"   iyz="0"
	                                                   izz="0.010379737" />
    </inertial>
  </link>
  <joint name="base_link_joint" type="fixed">
    <origin xyz="0 0 0.023249" rpy="0 0 0" />
    <parent link="base_link" />
    <child link="chassis" />
  </joint>
  <link
    name="left_rear_wheel">
    <inertial>
      <origin
        xyz="0 0 0"
        rpy="0 1.5707 1.5707" />
     <mass value="0.042222" />
	   <inertia ixx="0.0000611771" ixy="0"            ixz="0"
	                               iyy="0.0000611771" iyz="0"
	                                                  izz="0.0000944606" />        
    </inertial>
    <visual>
      <origin
        xyz="0 0 0"
        rpy="0 1.5707 1.5707" />
      <geometry>
        <cylinder length="0.025" radius="0.03" />
      </geometry>
    </visual>
    <collision>
      <origin
        xyz="0 0 0"
        rpy="0 1.5707 1.5707" />
      <geometry>
        <cylinder length="0.025" radius="0.03" />
      </geometry>

    </collision>
  </link>
  <joint
    name="left_rear_wheel_joint"
    type="continuous">
    <origin
      xyz="-0.081663 0.08105 0.01575"
      rpy="0 0 0" />
    <parent
      link="chassis" />
    <child
      link="left_rear_wheel" />
    <axis
      xyz="0 1 0" />
    <limit
      lower="-1"
      upper="1"
      effort="10"
      velocity="100" />
  </joint>
  <link
    name="right_rear_wheel">
    <inertial>
      <origin
        xyz="0 0 0"
        rpy="0 1.5707 1.5707" />
     <mass value="0.042222" />
	   <inertia ixx="0.0000611771" ixy="0"            ixz="0"
	                               iyy="0.0000611771" iyz="0"
	                                                  izz="0.0000944606" />        

    </inertial>
    <visual>
      <origin
        xyz="0 0 0"
        rpy="0 1.5707 1.5707" />
      <geometry>
        <cylinder length="0.025" radius="0.03" />
      </geometry>
    </visual>
    <collision>
      <origin
        xyz="0 0 0"
        rpy="0 1.5707 1.5707" />
      <geometry>
        <cylinder length="0.025" radius="0.03" />
      </geometry>
    </collision>
  </link>
  <joint
    name="right_rear_wheel_joint"
    type="continuous">
    <origin
      xyz="-0.081663 -0.08105 0.01575"
      rpy="0 0 0" />
    <parent
      link="chassis" />
    <child
      link="right_rear_wheel" />
    <axis
      xyz="0 1 0" />
    <limit
      lower="-1"
      upper="1"
      effort="10"
      velocity="100" />
  </joint>
  <link
    name="left_steering_hinge">
    <inertial>
      <origin
        xyz="0 0 0"
        rpy="0 0 0" />
      <mass value="0.050" />
      <inertia
        ixx="4E-06"
        ixy="0"
        ixz="0"
        iyy="4E-06"
        iyz="0"
        izz="4E-06" />
    </inertial>
    <visual>
      <origin
        xyz="0 0 0"
        rpy="0 0 0" />
      <geometry>
        <mesh
          filename="package://meshes/left_steering_hinge.STL" />
      </geometry>
    </visual>
  </link>
  <joint
    name="left_steering_hinge_joint"
    type="continuous">
    <origin
      xyz="0.082311 0.079601 0.011759"
      rpy="0 0 0" />
    <parent
      link="chassis" />
    <child
      link="left_steering_hinge" />
    <axis
      xyz="0 0 1" />
    <limit
      lower="-1"
      upper="1"
      effort="10"
      velocity="100" />
  </joint>
  <link
    name="left_front_wheel">
    <inertial>
      <origin
        xyz="0 0 0"
        rpy="0 1.5707 1.5707" />
     <mass value="0.042222" />
	   <inertia ixx="0.0000611771" ixy="0"            ixz="0"
	                               iyy="0.0000611771" iyz="0"
	                                                  izz="0.0000944606" />        

    </inertial>
    <visual>
      <origin
        xyz="0 0 0"
        rpy="0 1.5707 1.5707" />
      <geometry>
        <cylinder length="0.025" radius="0.03" />
      </geometry>
    </visual>
    <collision>
      <origin
        xyz="0 0 0"
        rpy="0 1.5707 1.5707" />
      <geometry>
        <cylinder length="0.025" radius="0.03" />
      </geometry>
    </collision>
  </link>
  <joint
    name="left_front_wheel_joint"
    type="continuous">
    <origin
      xyz="0 0 0"
      rpy="0 0 0" />
    <parent
      link="left_steering_hinge" />
    <child
      link="left_front_wheel" />
    <axis
      xyz="0 1 0" />
    <limit
      lower="-1"
      upper="1"
      effort="10"
      velocity="100" />
  </joint>
  <link
    name="right_steering_hinge">
    <inertial>
      <origin
        xyz="0 0 0"
        rpy="0 0 0" />
        <mass value="0.050" />
      <inertia
        ixx="4E-06"
        ixy="0"
        ixz="0"
        iyy="4E-06"
        iyz="0"
        izz="4E-06" />
    </inertial>
    <visual>
      <origin
        xyz="0 0 0"
        rpy="0 0 0" />
      <geometry>
        <mesh
          filename="package://meshes/right_steering_hinge.STL" />
      </geometry>
    </visual>
  </link>
  <joint
    name="right_steering_hinge_joint"
    type="continuous">
    <origin
      xyz="0.082311 -0.079601 0.011759"
      rpy="0 0 0" />
    <parent
      link="chassis" />
    <child
      link="right_steering_hinge" />
    <axis
      xyz="0 0 1" />
    <limit
      lower="-1"
      upper="1"
      effort="10"
      velocity="100" />
  </joint>
  <link
    name="right_front_wheel">
      <inertial>
      <origin
        xyz="0 0 0"
        rpy="0 1.5707 1.5707" />
     <mass value="0.042222" />
	   <inertia ixx="0.0000611771" ixy="0"            ixz="0"
	                               iyy="0.0000611771" iyz="0"
	                                                  izz="0.0000944606" />        

    </inertial>
    <visual>
      <origin
        xyz="0 0 0"
        rpy="0 1.5707 1.5707" />
      <geometry>
        <cylinder length="0.025" radius="0.03" />
      </geometry>
    </visual>
    <collision>
      <origin
        xyz="0 0 0"
        rpy="0 1.5707 1.5707" />
      <geometry>
        <cylinder length="0.025" radius="0.03" />
      </geometry>
    </collision>
  </link>
  <joint
    name="right_front_wheel_joint"
    type="continuous">
    <origin
      xyz="0 0 0"
      rpy="0 0 0" />
    <parent
      link="right_steering_hinge" />
    <child
      link="right_front_wheel" />
    <axis
      xyz="0 1 0" />
    <limit
      lower="-1"
      upper="1"
      effort="10"
      velocity="100" />
  </joint>
  <link
    name="zed_camera_link">
    <inertial>
      <origin
        xyz="0.019881 6.2875E-05 0.034966"
        rpy="0 0 0" />
      <mass
        value="1e-3" />
      <inertia
        ixx="1E-06"
        ixy="0"
        ixz="0"
        iyy="1E-06"
        iyz="0"
        izz="1E-06" />
    </inertial>
    <xacro:if value="${'deepracer' in shell_val}">
      <visual>
        <origin
          xyz="0 0 0"
          rpy="0 0 0" />
        <geometry>
          <mesh
            filename="package://meshes/zed_camera_link.STL" />
        </geometry>
      </visual>
    </xacro:if>
  </link>
  <joint
    name="zed_camera_joint"
    type="fixed">
    <origin
      xyz="0.091711 0 0.080023"
      rpy="0 0.2618 0" />
    <parent
      link="chassis" />
    <child
      link="zed_camera_link" />
    <axis
      xyz="0 0 0" />
  </joint>
  <link
    name="camera_link">
    <inertial>
      <origin
        xyz="0.0005 0 0"
        rpy="0 0 0" />
      <mass
        value="0.001" />
      <inertia
        ixx="1E-06"
        ixy="0"
        ixz="0"
        iyy="1E-06"
        iyz="0"
        izz="1E-06" />
    </inertial>
  </link>
  <joint
    name="camera_joint"
    type="fixed">
    <origin
      xyz="0.044755 0 0.04"
      rpy="0 0 0" />
    <parent
      link="zed_camera_link" />
    <child
      link="camera_link" />
    <axis
      xyz="0 0 0" />
  </joint>
  <link
    name="shell">
    <inertial>
      <origin
        xyz="0 0 0"
        rpy="0 0 0" />
      <mass
        value="0" />
      <inertia
        ixx="0"
        ixy="0"
        ixz="0"
        iyy="0"
        iyz="0"
        izz="0" />
    </inertial>
    <visual>
      <origin
        xyz="0 0 0"
        rpy="0 0 0" />
      <geometry>
        <mesh
          filename="package://meshes/$(arg shell)" />
      </geometry>
    </visual>
    <collision>
      <origin
        xyz="0 0 0"
        rpy="0 0 0" />
      <geometry>
        <mesh
          filename="package://meshes/$(arg shell)" />
      </geometry>
    </collision>
  </link>
  <joint
    name="shell_joint"
    type="fixed">
    <origin
      xyz="$(arg shell_joint_origin_x) $(arg shell_joint_origin_y) $(arg shell_joint_origin_z)"
      rpy="0 0 0" />
    <parent
      link="chassis" />
    <child
      link="shell" />
    <axis
      xyz="0 0 0" />
  </joint>
</robot>